2025-03-20 14:15:54,806 INFO    MainThread:13744 [wandb_setup.py:_flush():68] Current SDK version is 0.19.4
2025-03-20 14:15:54,806 INFO    MainThread:13744 [wandb_setup.py:_flush():68] Configure stats pid to 13744
2025-03-20 14:15:54,806 INFO    MainThread:13744 [wandb_setup.py:_flush():68] Loading settings from C:\Users\Simon\.config\wandb\settings
2025-03-20 14:15:54,806 INFO    MainThread:13744 [wandb_setup.py:_flush():68] Loading settings from C:\Users\Simon\Bachelorarbeit\EQL\eql\wandb\settings
2025-03-20 14:15:54,806 INFO    MainThread:13744 [wandb_setup.py:_flush():68] Loading settings from environment variables
2025-03-20 14:15:54,806 INFO    MainThread:13744 [wandb_init.py:setup_run_log_directory():624] Logging user logs to C:\Users\Simon\Bachelorarbeit\EQL\eql\wandb\run-20250320_141554-zd6ponqz\logs\debug.log
2025-03-20 14:15:54,806 INFO    MainThread:13744 [wandb_init.py:setup_run_log_directory():625] Logging internal logs to C:\Users\Simon\Bachelorarbeit\EQL\eql\wandb\run-20250320_141554-zd6ponqz\logs\debug-internal.log
2025-03-20 14:15:54,811 INFO    MainThread:13744 [wandb_init.py:init():743] calling init triggers
2025-03-20 14:15:54,811 INFO    MainThread:13744 [wandb_init.py:init():748] wandb.init called with sweep_config: {'_target_': 'jax.random.PRNGKey', 'batchsize': 10000, 'depth': 1, 'epochs': 20000, 'in_size': 2, 'l0_threshold': 0.001, 'loss_type': 'mse', 'lr_start': 0.001, 'out_size': 1, 'seed': 0, 'width_size': 15}
config: {'in_size': 3, 'out_size': 1, 'width_size': 21, 'depth': 2, '_target_': 'jax.random.PRNGKey', 'seed': 1, 'epochs': 20000, 'batchsize': 10000, 'loss_type': 'mse', 'lr_start': 0.001, 'l0_threshold': 0.001, 'wandb': {'setup': {'entity': 'simonb03-university-of-t-bingen'}}, 'sweep': {'program': 'main_OPR.py', 'name': 'OPR_sweep', 'metric': {'name': 'val_loss', 'goal': 'minimize'}, 'method': 'grid', 'parameters': {'in_size': {'values': [2, 3, 4]}, 'out_size': {'value': 1}, 'width_size': {'values': [12, 15, 18]}, 'depth': {'values': [1, 2]}, '_target_': {'value': 'jax.random.PRNGKey'}, 'seed': {'value': 0}, 'epochs': {'value': 20000}, 'batchsize': {'value': 10000}, 'loss_type': {'value': 'mse'}, 'lr_start': {'values': [0.001, 0.0001]}, 'l0_threshold': {'value': 0.001}}, 'command': ['C:/Users/Simon/.conda/envs/EQL/python.exe', 'main_OPR.py']}}
2025-03-20 14:15:54,811 INFO    MainThread:13744 [wandb_init.py:init():776] starting backend
2025-03-20 14:15:56,849 INFO    MainThread:13744 [wandb_init.py:init():780] sending inform_init request
2025-03-20 14:15:56,877 INFO    MainThread:13744 [backend.py:_multiprocessing_setup():97] multiprocessing start_methods=spawn, using: spawn
2025-03-20 14:15:56,879 INFO    MainThread:13744 [wandb_init.py:init():795] backend started and connected
2025-03-20 14:15:56,880 INFO    MainThread:13744 [wandb_run.py:_config_callback():1270] config_cb None None {'_target_': 'jax.random.PRNGKey', 'batchsize': 10000, 'depth': 1, 'epochs': 20000, 'in_size': 2, 'l0_threshold': 0.001, 'loss_type': 'mse', 'lr_start': 0.001, 'out_size': 1, 'seed': 0, 'width_size': 15}
2025-03-20 14:15:56,882 INFO    MainThread:13744 [wandb_init.py:init():888] updated telemetry
2025-03-20 14:15:56,934 INFO    MainThread:13744 [wandb_init.py:init():915] communicating run to backend with 90.0 second timeout
2025-03-20 14:15:57,704 INFO    MainThread:13744 [wandb_init.py:init():967] starting run threads in backend
2025-03-20 14:16:00,469 INFO    MainThread:13744 [wandb_run.py:_console_start():2409] atexit reg
2025-03-20 14:16:00,470 INFO    MainThread:13744 [wandb_run.py:_redirect():2259] redirect: wrap_raw
2025-03-20 14:16:00,470 INFO    MainThread:13744 [wandb_run.py:_redirect():2324] Wrapping output streams.
2025-03-20 14:16:00,471 INFO    MainThread:13744 [wandb_run.py:_redirect():2349] Redirects installed.
2025-03-20 14:16:00,477 INFO    MainThread:13744 [wandb_init.py:init():1009] run started, returning control to user process
2025-03-20 14:18:36,138 INFO    MainThread:13744 [retry.py:__call__():172] Retry attempt failed:
Traceback (most recent call last):
  File "C:\Users\Simon\.conda\envs\EQL\Lib\site-packages\urllib3\connection.py", line 198, in _new_conn
    sock = connection.create_connection(
           ^^^^^^^^^^^^^^^^^^^^^^^^^^^^^
  File "C:\Users\Simon\.conda\envs\EQL\Lib\site-packages\urllib3\util\connection.py", line 60, in create_connection
    for res in socket.getaddrinfo(host, port, family, socket.SOCK_STREAM):
               ^^^^^^^^^^^^^^^^^^^^^^^^^^^^^^^^^^^^^^^^^^^^^^^^^^^^^^^^^^
  File "C:\Users\Simon\.conda\envs\EQL\Lib\socket.py", line 974, in getaddrinfo
    for res in _socket.getaddrinfo(host, port, family, type, proto, flags):
               ^^^^^^^^^^^^^^^^^^^^^^^^^^^^^^^^^^^^^^^^^^^^^^^^^^^^^^^^^^^
socket.gaierror: [Errno 11001] getaddrinfo failed

The above exception was the direct cause of the following exception:

Traceback (most recent call last):
  File "C:\Users\Simon\.conda\envs\EQL\Lib\site-packages\urllib3\connectionpool.py", line 787, in urlopen
    response = self._make_request(
               ^^^^^^^^^^^^^^^^^^^
  File "C:\Users\Simon\.conda\envs\EQL\Lib\site-packages\urllib3\connectionpool.py", line 488, in _make_request
    raise new_e
  File "C:\Users\Simon\.conda\envs\EQL\Lib\site-packages\urllib3\connectionpool.py", line 464, in _make_request
    self._validate_conn(conn)
  File "C:\Users\Simon\.conda\envs\EQL\Lib\site-packages\urllib3\connectionpool.py", line 1093, in _validate_conn
    conn.connect()
  File "C:\Users\Simon\.conda\envs\EQL\Lib\site-packages\urllib3\connection.py", line 704, in connect
    self.sock = sock = self._new_conn()
                       ^^^^^^^^^^^^^^^^
  File "C:\Users\Simon\.conda\envs\EQL\Lib\site-packages\urllib3\connection.py", line 205, in _new_conn
    raise NameResolutionError(self.host, self, e) from e
urllib3.exceptions.NameResolutionError: <urllib3.connection.HTTPSConnection object at 0x000001DC8B4E0590>: Failed to resolve 'api.wandb.ai' ([Errno 11001] getaddrinfo failed)

The above exception was the direct cause of the following exception:

Traceback (most recent call last):
  File "C:\Users\Simon\.conda\envs\EQL\Lib\site-packages\requests\adapters.py", line 667, in send
    resp = conn.urlopen(
           ^^^^^^^^^^^^^
  File "C:\Users\Simon\.conda\envs\EQL\Lib\site-packages\urllib3\connectionpool.py", line 841, in urlopen
    retries = retries.increment(
              ^^^^^^^^^^^^^^^^^^
  File "C:\Users\Simon\.conda\envs\EQL\Lib\site-packages\urllib3\util\retry.py", line 519, in increment
    raise MaxRetryError(_pool, url, reason) from reason  # type: ignore[arg-type]
    ^^^^^^^^^^^^^^^^^^^^^^^^^^^^^^^^^^^^^^^^^^^^^^^^^^^
urllib3.exceptions.MaxRetryError: HTTPSConnectionPool(host='api.wandb.ai', port=443): Max retries exceeded with url: /graphql (Caused by NameResolutionError("<urllib3.connection.HTTPSConnection object at 0x000001DC8B4E0590>: Failed to resolve 'api.wandb.ai' ([Errno 11001] getaddrinfo failed)"))

During handling of the above exception, another exception occurred:

Traceback (most recent call last):
  File "C:\Users\Simon\.conda\envs\EQL\Lib\site-packages\wandb\sdk\lib\retry.py", line 131, in __call__
    result = self._call_fn(*args, **kwargs)
             ^^^^^^^^^^^^^^^^^^^^^^^^^^^^^^
  File "C:\Users\Simon\.conda\envs\EQL\Lib\site-packages\wandb\sdk\internal\internal_api.py", line 393, in execute
    return self.client.execute(*args, **kwargs)  # type: ignore
           ^^^^^^^^^^^^^^^^^^^^^^^^^^^^^^^^^^^^
  File "C:\Users\Simon\.conda\envs\EQL\Lib\site-packages\wandb\vendor\gql-0.2.0\wandb_gql\client.py", line 52, in execute
    result = self._get_result(document, *args, **kwargs)
             ^^^^^^^^^^^^^^^^^^^^^^^^^^^^^^^^^^^^^^^^^^^
  File "C:\Users\Simon\.conda\envs\EQL\Lib\site-packages\wandb\vendor\gql-0.2.0\wandb_gql\client.py", line 60, in _get_result
    return self.transport.execute(document, *args, **kwargs)
           ^^^^^^^^^^^^^^^^^^^^^^^^^^^^^^^^^^^^^^^^^^^^^^^^^
  File "C:\Users\Simon\.conda\envs\EQL\Lib\site-packages\wandb\sdk\lib\gql_request.py", line 58, in execute
    request = self.session.post(self.url, **post_args)
              ^^^^^^^^^^^^^^^^^^^^^^^^^^^^^^^^^^^^^^^^
  File "C:\Users\Simon\.conda\envs\EQL\Lib\site-packages\requests\sessions.py", line 637, in post
    return self.request("POST", url, data=data, json=json, **kwargs)
           ^^^^^^^^^^^^^^^^^^^^^^^^^^^^^^^^^^^^^^^^^^^^^^^^^^^^^^^^^
  File "C:\Users\Simon\.conda\envs\EQL\Lib\site-packages\requests\sessions.py", line 589, in request
    resp = self.send(prep, **send_kwargs)
           ^^^^^^^^^^^^^^^^^^^^^^^^^^^^^^
  File "C:\Users\Simon\.conda\envs\EQL\Lib\site-packages\requests\sessions.py", line 703, in send
    r = adapter.send(request, **kwargs)
        ^^^^^^^^^^^^^^^^^^^^^^^^^^^^^^^
  File "C:\Users\Simon\.conda\envs\EQL\Lib\site-packages\requests\adapters.py", line 700, in send
    raise ConnectionError(e, request=request)
requests.exceptions.ConnectionError: HTTPSConnectionPool(host='api.wandb.ai', port=443): Max retries exceeded with url: /graphql (Caused by NameResolutionError("<urllib3.connection.HTTPSConnection object at 0x000001DC8B4E0590>: Failed to resolve 'api.wandb.ai' ([Errno 11001] getaddrinfo failed)"))
2025-03-20 14:19:09,768 INFO    MainThread:13744 [wandb_run.py:_finish():2134] finishing run simonb03-university-of-t-bingen/OPR_sweep/zd6ponqz
2025-03-20 14:19:09,768 INFO    MainThread:13744 [wandb_run.py:_atexit_cleanup():2374] got exitcode: 0
2025-03-20 14:19:09,768 INFO    MainThread:13744 [wandb_run.py:_restore():2356] restore
2025-03-20 14:19:09,768 INFO    MainThread:13744 [wandb_run.py:_restore():2362] restore done
2025-03-20 14:19:16,121 INFO    MainThread:13744 [wandb_run.py:_footer_history_summary_info():3976] rendering history
2025-03-20 14:19:16,121 INFO    MainThread:13744 [wandb_run.py:_footer_history_summary_info():4008] rendering summary
2025-03-20 14:19:16,121 INFO    MainThread:13744 [wandb_run.py:_footer_sync_info():3937] logging synced files
